Workbook
Name борт_2013: Ценообразование!$B$9:$D$11
Name борт_2513: Ценообразование!$B$12:$D$14
Name борт_2515: Ценообразование!$B$15:$D$17
Name борт_3015: Ценообразование!$B$18:$D$20
Name борт_3515: Ценообразование!$B$21:$D$23
Name борт_4015: Ценообразование!$B$24:$D$26
Name колесо: Ценообразование!$B$27:$D$29
Name Кузов_2013: 'Виды прицепов'!$C$4:$I$6
Name кузов_2513: 'Виды прицепов'!$C$7:$N$9
Name кузов_2515: 'Виды прицепов'!$C$10:$I$12
Name кузов_3015: 'Виды прицепов'!$C$13:$I$15
Name кузов_3515: 'Виды прицепов'!$C$16:$I$18
Name кузов_4015: 'Виды прицепов'!$C$19:$N$21
Name матрица: 'Матрица основная'!$A$4:$Q$509
Name опорное_колесо: Ценообразование!$B$33:$D$34
Name Платформа: Ценообразование!$A$2:$B$7
Name платформа2: Ценообразование!$E$4:$F$7
Name Покупатели: Покупатели!$C$1:$N$835
Name ПРИЦЕПЫ: Прицепы!$C$2:$N$1073
Name Реестр_Договоров: 'Реестр договоров'!$A$1:$D$899
Name Св_табл_ЮЛ: 'Сводная таблица ЮЛ'!$A$1:$AB$57
Name Сводная_таблица: 'Сводная таблица ЮЛ'!$A$2:$U$407
Name Сводная_таблица: 'Сводная таблица ФЛ'!$A$2:$U$899
Name ступица: Ценообразование!$B$30:$D$32
Name тент_2013: Ценообразование!$B$35:$D$38
Name тент_2513: Ценообразование!$B$39:$D$42
Name тент_2515: Ценообразование!$B$43:$D$45
Name тент_3015: Ценообразование!$B$46:$D$48
Name тент_3515: Ценообразование!$B$49:$C$51
Name тент_4015: Ценообразование!$B$52:$D$54
Name Юр_лица: 'юр лица'!$C$1:$T$38

Sheet Реестр договоров
B1: дата | C1: фамилия | D1: VIN
A2: 1161 | B2: 45447 | C2: =Покупатели!C2 -> Белоногова | D2: =VLOOKUP(C2,Покупатели!$C$2:$Q$738,15,0) -> MX4000002R0001522
A3: 1162 | B3: 45449 | C3: =Покупатели!C3 -> Рахманов | D3: =VLOOKUP(C3,Покупатели!$C$2:$Q$738,15,0) -> MX4000002R0001502
A4: 1163 | B4: 45450 | C4: =Покупатели!C6 -> Кулиева | D4: =VLOOKUP(C4,Покупатели!$C$2:$Q$738,15,0) -> MX4000002R0001511
A5: 1164 | B5: 45451 | C5: =Покупатели!C4 -> Петрик | D5: =VLOOKUP(C5,Покупатели!$C$2:$Q$738,15,0) -> MX4000002R0001518
A6: 1165 | B6: 45451 | C6: =Покупатели!C5 -> Ребенков | D6: =VLOOKUP(C6,Покупатели!$C$2:$Q$738,15,0) -> MX4000002R0001573
A7: 1166 | B7: 45451 | C7: =Покупатели!C7 -> Темирбаев | D7: =VLOOKUP(C7,Покупатели!$C$2:$Q$738,15,0) -> MX4000002R0001455
A8: 1167 | B8: 45453 | C8: =Покупатели!C8 -> Доспергенов | D8: =VLOOKUP(C8,Покупатели!$C$2:$Q$738,15,0) -> MX4000002R0001719
A9: 1168 | B9: 45451 | C9: =Покупатели!C9 -> Касымов | D9: =VLOOKUP(C9,Покупатели!$C$2:$Q$738,15,0) -> MX4000002R0001642
A10: 1169 | B10: 45455 | C10: =Покупатели!C10 -> Сулейменов 2 | D10: =VLOOKUP(C10,Покупатели!$C$2:$Q$738,15,0) -> MX4000002R0001659
A11: 1170 | B11: 45460 | C11: =Покупатели!C11 -> Курбанова | D11: =VLOOKUP(C11,Покупатели!$C$2:$Q$738,15,0) -> MX4000002R0001508
A12: 1171 | B12: 45461 | C12: =Покупатели!C12 -> Абайқызы | D12: =VLOOKUP(C12,Покупатели!$C$2:$Q$738,15,0) -> MX4000002R0001517
A13: 1172 | B13: 45461 | C13: =Покупатели!C13 -> Меньшиков | D13: =VLOOKUP(C13,Покупатели!$C$2:$Q$738,15,0) -> MX4000002R0001538
A14: 1173 | B14: 45462 | C14: =Покупатели!C14 -> Билочук | D14: =VLOOKUP(C14,Покупатели!$C$2:$Q$738,15,0) -> MX4000002R0001653
A15: 1174 | B15: 45463 | C15: =Покупатели!C15 -> Ягминас | D15: =VLOOKUP(C15,Покупатели!$C$2:$Q$738,15,0) -> MX4000002R0001654
A16: 1175 | B16: 45464 | C16: =Покупатели!C16 -> Костюков1 | D16: =VLOOKUP(C16,Покупатели!$C$2:$Q$738,15,0) -> MX4000002R0001506
A17: 1176 | B17: 45464 | C17: =Покупатели!C18 -> Байзаков | D17: =VLOOKUP(C17,Покупатели!$C$2:$Q$738,15,0) -> MX4000002R0001680
A18: 1177 | B18: 45464 | C18: =Покупатели!C17 -> Оспанова | D18: =VLOOKUP(C18,Покупатели!$C$2:$Q$738,15,0) -> MX4000002R0001497
A19: 1178 | B19: 45464 | C19: =Покупатели!C19 -> Шапарев | D19: =VLOOKUP(C19,Покупатели!$C$2:$Q$738,15,0) -> MX4000002R0001516
A20: 1179 | B20: 45464 | C20: =Покупатели!C20 -> Бикенова | D20: =VLOOKUP(C20,Покупатели!$C$2:$Q$738,15,0) -> MX4000002R0001643
A21: 1180 | B21: 45464 | C21: =Покупатели!C21 -> Боровиков | D21: =VLOOKUP(C21,Покупатели!$C$2:$Q$738,15,0) -> MX4000002R0001521
A22: 1181 | B22: 45465 | C22: =Покупатели!C22 -> Гаврилюк | D22: =VLOOKUP(C22,Покупатели!$C$2:$Q$738,15,0) -> MX4000002R0001572
A23: 1182 | B23: 45465 | C23: =Покупатели!C23 -> Каримов | D23: =VLOOKUP(C23,Покупатели!$C$2:$Q$738,15,0) -> MX4000002R0001481
A24: 1183 | B24: 45465 | C24: =Покупатели!C24 -> Базимов | D24: =VLOOKUP(C24,Покупатели!$C$2:$Q$738,15,0) -> MX4000002R0001569
A25: 1184 | B25: 45465 | C25: =Покупатели!C25 -> Жунусов1 | D25: =VLOOKUP(C25,Покупатели!$C$2:$Q$738,15,0) -> MX4000002R0001500
A26: 1185 | B26: 45465 | C26: =Покупатели!C26 -> Бирюков | D26: =VLOOKUP(C26,Покупатели!$C$2:$Q$738,15,0) -> MX4000002R0001571
A27: 1186 | B27: 45467 | C27: =Покупатели!C27 -> Сейдахмет | D27: =VLOOKUP(C27,Покупатели!$C$2:$Q$738,15,0) -> MX4000002R0001507
A28: 1187 | B28: 45467 | C28: =Покупатели!C28 -> Некерев | D28: =VLOOKUP(C28,Покупатели!$C$2:$Q$738,15,0) -> MX4000002R0001468
A29: 1188 | B29: 45467 | C29: =Покупатели!C29 -> Мещеряков | D29: =VLOOKUP(C29,Покупатели!$C$2:$Q$738,15,0) -> MX4000002R0001664
A30: 1189 | B30: 45467 | C30: =Покупатели!C30 -> Айтимов 1 | D30: =VLOOKUP(C30,Покупатели!$C$2:$Q$738,15,0) -> MX4000002R0001462
... A52: 1211 | B52: 45475 | C52: =Покупатели!C52 -> Дуйсеков | D52: =VLOOKUP(C52,Покупатели!$C$2:$Q$738,15,0) -> MX4000002R0001574
A53: 1212 | B53: 45475 | C53: =Покупатели!C54 -> Грабовский | D53: =VLOOKUP(C53,Покупатели!$C$2:$Q$738,15,0) -> MX4000002R0001663
A54: 1213 | B54: 45476 | C54: =Покупатели!C53 -> Пияшкин | D54: =VLOOKUP(C54,Покупатели!$C$2:$Q$738,15,0) -> MX4000002R0001671
A55: 1214 | B55: 45476 | C55: =Покупатели!C55 -> Жумангужина | D55: =VLOOKUP(C55,Покупатели!$C$2:$Q$738,15,0) -> MX4000002R0001657
A56: 1215 | B56: 45476 | C56: =Покупатели!C56 -> Белгибаева | D56: =VLOOKUP(C56,Покупатели!$C$2:$Q$738,15,0) -> MX4000002R0001677
A57: 1216 | B57: 45476 | C57: =Покупатели!C57 -> Харламов 1 | D57: =VLOOKUP(C57,Покупатели!$C$2:$Q$738,15,0) -> MX4000002R0001509
A58: 1217 | B58: 45477 | C58: =Покупатели!C58 -> Батяйкин | D58: =VLOOKUP(C58,Покупатели!$C$2:$Q$738,15,0) -> MX4000004R0001606
A59: 1218 | B59: 45478 | C59: =Покупатели!C60 -> Волкова | D59: =VLOOKUP(C59,Покупатели!$C$2:$Q$738,15,0) -> MX4000002R0001560
A60: 1219 | B60: 45478 | C60: =Покупатели!C61 -> Бопышев | D60: =VLOOKUP(C60,Покупатели!$C$2:$Q$738,15,0) -> MX4000002R0001647
A61: 1220 | B61: 45478 | C61: =Покупатели!C62 -> Дерюгин | D61: =VLOOKUP(C61,Покупатели!$C$2:$Q$738,15,0) -> MX4000002R0001460
...

Sheet Прицепы
A1: Отметка времени | C1: VIN код | D1: Прицеп | E1: Борт | F1: Колесо | G1: Ступица | H1: Тент-каркас | I1: Дата выпуска | J1: Откатное колесо | K1: Склад | L1: Количество осей | M1: Артикул | N1: Статус
A2: 45520.74 | C2: MX4000003R0001752 | D2: Прицеп 2,0*1,25 м (до 750 кг.) | E2: нет | F2: нет | G2: R13 | H2: нет | I2: 45520 | J2: есть | K2: Кокшетау | L2: 1 ось | M2: =IFERROR(__xludf.DUMMYFUNCTION("JOIN("""",VLOOKUP(D2,'для артикула'!$A$2:$B$7,2,0),VLOOKUP(G2,'для артикула'!$A$13:$B$14,2,0),VLOOKUP(E2,'для артикула'!$A$9:$B$11,2,0),VLOOKUP(F2,'для артикула'!$A$17:$B$19,2,0),VLOOKUP(J2,'для артикула'!$A$22:$B$23,2,0),VLOOKUP(H2,'для артикула'!$A$26:$"&"B$30,2,0))"),"002-2013-OK") -> 002-2013-OK | N2: =IF(ISNUMBER(MATCH(C2, 'Реестр договоров'!$D$2:$D$900, 0)), "Продано", "В наличии") -> Продано
A3: 45632.55 | C3: MX4000002R0001856 | D3: Прицеп 2,0*1,25 м (до 750 кг.) | E3: 50 | F3: R13 | G3: R13 | H3: нет | I3: 45628 | J3: есть | K3: Алматы | L3: 1 ось | M3: =IFERROR(__xludf.DUMMYFUNCTION("JOIN("""",VLOOKUP(D3,'для артикула'!$A$2:$B$7,2,0),VLOOKUP(G3,'для артикула'!$A$13:$B$14,2,0),VLOOKUP(E3,'для артикула'!$A$9:$B$11,2,0),VLOOKUP(F3,'для артикула'!$A$17:$B$19,2,0),VLOOKUP(J3,'для артикула'!$A$22:$B$23,2,0),VLOOKUP(H3,'для артикула'!$A$26:$"&"B$30,2,0))"),"002-2013E50Q13-OK") -> 002-2013E50Q13-OK | N3: =IF(ISNUMBER(MATCH(C3, 'Реестр договоров'!$D$2:$D$900, 0)), "Продано", "В наличии") -> Продано
A4: 45646.439 | C4: MX4000002R0001852 | D4: Прицеп 2,0*1,25 м (до 750 кг.) | E4: 50 | F4: R13 | G4: R13 | H4: нет | I4: 45641 | J4: есть | K4: Алматы | L4: 1 ось | M4: =IFERROR(__xludf.DUMMYFUNCTION("JOIN("""",VLOOKUP(D4,'для артикула'!$A$2:$B$7,2,0),VLOOKUP(G4,'для артикула'!$A$13:$B$14,2,0),VLOOKUP(E4,'для артикула'!$A$9:$B$11,2,0),VLOOKUP(F4,'для артикула'!$A$17:$B$19,2,0),VLOOKUP(J4,'для артикула'!$A$22:$B$23,2,0),VLOOKUP(H4,'для артикула'!$A$26:$"&"B$30,2,0))"),"002-2013E50Q13-OK") -> 002-2013E50Q13-OK | N4: =IF(ISNUMBER(MATCH(C4, 'Реестр договоров'!$D$2:$D$900, 0)), "Продано", "В наличии") -> Продано
A5: 45617.566 | C5: MX4000002R0001849 | D5: Прицеп 2,0*1,25 м (до 750 кг.) | E5: 50 | F5: R13 | G5: R13 | H5: нет | I5: 45617 | J5: есть | K5: Алматы | L5: 1 ось | M5: =IFERROR(__xludf.DUMMYFUNCTION("JOIN("""",VLOOKUP(D5,'для артикула'!$A$2:$B$7,2,0),VLOOKUP(G5,'для артикула'!$A$13:$B$14,2,0),VLOOKUP(E5,'для артикула'!$A$9:$B$11,2,0),VLOOKUP(F5,'для артикула'!$A$17:$B$19,2,0),VLOOKUP(J5,'для артикула'!$A$22:$B$23,2,0),VLOOKUP(H5,'для артикула'!$A$26:$"&"B$30,2,0))"),"002-2013E50Q13-OK") -> 002-2013E50Q13-OK | N5: =IF(ISNUMBER(MATCH(C5, 'Реестр договоров'!$D$2:$D$900, 0)), "Продано", "В наличии") -> Продано
A6: 45617.529 | C6: MX4000002R0001848 | D6: Прицеп 2,0*1,25 м (до 750 кг.) | E6: 50 | F6: R13 | G6: R13 | H6: нет | I6: 45617 | J6: есть | K6: Алматы | L6: 1 ось | M6: =IFERROR(__xludf.DUMMYFUNCTION("JOIN("""",VLOOKUP(D6,'для артикула'!$A$2:$B$7,2,0),VLOOKUP(G6,'для артикула'!$A$13:$B$14,2,0),VLOOKUP(E6,'для артикула'!$A$9:$B$11,2,0),VLOOKUP(F6,'для артикула'!$A$17:$B$19,2,0),VLOOKUP(J6,'для артикула'!$A$22:$B$23,2,0),VLOOKUP(H6,'для артикула'!$A$26:$"&"B$30,2,0))"),"002-2013E50Q13-OK") -> 002-2013E50Q13-OK | N6: =IF(ISNUMBER(MATCH(C6, 'Реестр договоров'!$D$2:$D$900, 0)), "Продано", "В наличии") -> Продано
A7: 45617.528 | C7: MX4000002R0001847 | D7: Прицеп 2,0*1,25 м (до 750 кг.) | E7: 50 | F7: R13 | G7: R13 | H7: нет | I7: 45617 | J7: есть | K7: Алматы | L7: 1 ось | M7: =IFERROR(__xludf.DUMMYFUNCTION("JOIN("""",VLOOKUP(D7,'для артикула'!$A$2:$B$7,2,0),VLOOKUP(G7,'для артикула'!$A$13:$B$14,2,0),VLOOKUP(E7,'для артикула'!$A$9:$B$11,2,0),VLOOKUP(F7,'для артикула'!$A$17:$B$19,2,0),VLOOKUP(J7,'для артикула'!$A$22:$B$23,2,0),VLOOKUP(H7,'для артикула'!$A$26:$"&"B$30,2,0))"),"002-2013E50Q13-OK") -> 002-2013E50Q13-OK | N7: =IF(ISNUMBER(MATCH(C7, 'Реестр договоров'!$D$2:$D$900, 0)), "Продано", "В наличии") -> Продано
A8: 45617.528 | C8: MX4000002R0001846 | D8: Прицеп 2,0*1,25 м (до 750 кг.) | E8: 50 | F8: R13 | G8: R13 | H8: нет | I8: 45617 | J8: есть | K8: Алматы | L8: 1 ось | M8: =IFERROR(__xludf.DUMMYFUNCTION("JOIN("""",VLOOKUP(D8,'для артикула'!$A$2:$B$7,2,0),VLOOKUP(G8,'для артикула'!$A$13:$B$14,2,0),VLOOKUP(E8,'для артикула'!$A$9:$B$11,2,0),VLOOKUP(F8,'для артикула'!$A$17:$B$19,2,0),VLOOKUP(J8,'для артикула'!$A$22:$B$23,2,0),VLOOKUP(H8,'для артикула'!$A$26:$"&"B$30,2,0))"),"002-2013E50Q13-OK") -> 002-2013E50Q13-OK | N8: =IF(ISNUMBER(MATCH(C8, 'Реестр договоров'!$D$2:$D$900, 0)), "Продано", "В наличии") -> Продано
A9: 45637.773 | C9: MX4000002R0001838 | D9: Прицеп 2,0*1,25 м (до 750 кг.) | E9: 50 | F9: R13 | G9: R13 | H9: нет | I9: 45637 | J9: есть | K9: Астана | L9: 1 ось | M9: =IFERROR(__xludf.DUMMYFUNCTION("JOIN("""",VLOOKUP(D9,'для артикула'!$A$2:$B$7,2,0),VLOOKUP(G9,'для артикула'!$A$13:$B$14,2,0),VLOOKUP(E9,'для артикула'!$A$9:$B$11,2,0),VLOOKUP(F9,'для артикула'!$A$17:$B$19,2,0),VLOOKUP(J9,'для артикула'!$A$22:$B$23,2,0),VLOOKUP(H9,'для артикула'!$A$26:$"&"B$30,2,0))"),"002-2013E50Q13-OK") -> 002-2013E50Q13-OK | N9: =IF(ISNUMBER(MATCH(C9, 'Реестр договоров'!$D$2:$D$900, 0)), "Продано", "В наличии") -> Продано
A10: 45610.653 | C10: MX4000002R0001837 | D10: Прицеп 2,0*1,25 м (до 750 кг.) | E10: 50 | F10: R13 | G10: R13 | H10: 30 | I10: 45610 | J10: есть | K10: Кокшетау | L10: 1 ось | M10: =IFERROR(__xludf.DUMMYFUNCTION("JOIN("""",VLOOKUP(D10,'для артикула'!$A$2:$B$7,2,0),VLOOKUP(G10,'для артикула'!$A$13:$B$14,2,0),VLOOKUP(E10,'для артикула'!$A$9:$B$11,2,0),VLOOKUP(F10,'для артикула'!$A$17:$B$19,2,0),VLOOKUP(J10,'для артикула'!$A$22:$B$23,2,0),VLOOKUP(H10,'для артикула'!$"&"A$26:$B$30,2,0))"),"002-2013E50Q13-OK30") -> 002-2013E50Q13-OK30 | N10: =IF(ISNUMBER(MATCH(C10, 'Реестр договоров'!$D$2:$D$900, 0)), "Продано", "В наличии") -> Продано
A11: 45604.421 | C11: MX4000002R0001836 | D11: Прицеп 2,0*1,25 м (до 750 кг.) | E11: 50 | F11: R13 | G11: R13 | H11: нет | I11: 45604 | J11: есть | K11: Кокшетау | L11: 1 ось | M11: =IFERROR(__xludf.DUMMYFUNCTION("JOIN("""",VLOOKUP(D11,'для артикула'!$A$2:$B$7,2,0),VLOOKUP(G11,'для артикула'!$A$13:$B$14,2,0),VLOOKUP(E11,'для артикула'!$A$9:$B$11,2,0),VLOOKUP(F11,'для артикула'!$A$17:$B$19,2,0),VLOOKUP(J11,'для артикула'!$A$22:$B$23,2,0),VLOOKUP(H11,'для артикула'!$"&"A$26:$B$30,2,0))"),"002-2013E50Q13-OK") -> 002-2013E50Q13-OK | N11: =IF(ISNUMBER(MATCH(C11, 'Реестр договоров'!$D$2:$D$900, 0)), "Продано", "В наличии") -> Продано
A12: 45637.812 | C12: MX4000002R0001831 | D12: Прицеп 2,0*1,25 м (до 750 кг.) | E12: 30 | F12: R13 | G12: R13 | H12: нет | I12: 45637 | J12: есть | K12: Астана | L12: 1 ось | M12: =IFERROR(__xludf.DUMMYFUNCTION("JOIN("""",VLOOKUP(D12,'для артикула'!$A$2:$B$7,2,0),VLOOKUP(G12,'для артикула'!$A$13:$B$14,2,0),VLOOKUP(E12,'для артикула'!$A$9:$B$11,2,0),VLOOKUP(F12,'для артикула'!$A$17:$B$19,2,0),VLOOKUP(J12,'для артикула'!$A$22:$B$23,2,0),VLOOKUP(H12,'для артикула'!$"&"A$26:$B$30,2,0))"),"002-2013E30Q13-OK") -> 002-2013E30Q13-OK | N12: =IF(ISNUMBER(MATCH(C12, 'Реестр договоров'!$D$2:$D$900, 0)), "Продано", "В наличии") -> Продано
A13: 45635.505 | C13: MX4000002R0001830 | D13: Прицеп 2,0*1,25 м (до 750 кг.) | E13: 50 | F13: R13 | G13: R13 | H13: нет | I13: 45628 | J13: есть | K13: Астана | L13: 1 ось | M13: =IFERROR(__xludf.DUMMYFUNCTION("JOIN("""",VLOOKUP(D13,'для артикула'!$A$2:$B$7,2,0),VLOOKUP(G13,'для артикула'!$A$13:$B$14,2,0),VLOOKUP(E13,'для артикула'!$A$9:$B$11,2,0),VLOOKUP(F13,'для артикула'!$A$17:$B$19,2,0),VLOOKUP(J13,'для артикула'!$A$22:$B$23,2,0),VLOOKUP(H13,'для артикула'!$"&"A$26:$B$30,2,0))"),"002-2013E50Q13-OK") -> 002-2013E50Q13-OK | N13: =IF(ISNUMBER(MATCH(C13, 'Реестр договоров'!$D$2:$D$900, 0)), "Продано", "В наличии") -> Продано
A14: 45629.598 | C14: MX4000002R0001827 | D14: Прицеп 2,0*1,25 м (до 750 кг.) | E14: 50 | F14: R13 | G14: R13 | H14: нет | I14: 45629 | J14: есть | K14: Алматы | L14: 1 ось | M14: =IFERROR(__xludf.DUMMYFUNCTION("JOIN("""",VLOOKUP(D14,'для артикула'!$A$2:$B$7,2,0),VLOOKUP(G14,'для артикула'!$A$13:$B$14,2,0),VLOOKUP(E14,'для артикула'!$A$9:$B$11,2,0),VLOOKUP(F14,'для артикула'!$A$17:$B$19,2,0),VLOOKUP(J14,'для артикула'!$A$22:$B$23,2,0),VLOOKUP(H14,'для артикула'!$"&"A$26:$B$30,2,0))"),"002-2013E50Q13-OK") -> 002-2013E50Q13-OK | N14: =IF(ISNUMBER(MATCH(C14, 'Реестр договоров'!$D$2:$D$900, 0)), "Продано", "В наличии") -> Продано
A15: 45617.528 | C15: MX4000002R0001826 | D15: Прицеп 2,0*1,25 м (до 750 кг.) | E15: 50 | F15: R13 | G15: R13 | H15: нет | I15: 45617 | J15: есть | K15: Алматы | L15: 1 ось | M15: =IFERROR(__xludf.DUMMYFUNCTION("JOIN("""",VLOOKUP(D15,'для артикула'!$A$2:$B$7,2,0),VLOOKUP(G15,'для артикула'!$A$13:$B$14,2,0),VLOOKUP(E15,'для артикула'!$A$9:$B$11,2,0),VLOOKUP(F15,'для артикула'!$A$17:$B$19,2,0),VLOOKUP(J15,'для артикула'!$A$22:$B$23,2,0),VLOOKUP(H15,'для артикула'!$"&"A$26:$B$30,2,0))"),"002-2013E50Q13-OK") -> 002-2013E50Q13-OK | N15: =IF(ISNUMBER(MATCH(C15, 'Реестр договоров'!$D$2:$D$900, 0)), "Продано", "В наличии") -> Продано
A16: 45617.601 | C16: MX4000002R0001825 | D16: Прицеп 2,0*1,25 м (до 750 кг.) | E16: 30 | F16: R13 | G16: R13 | H16: нет | I16: 45617 | J16: есть | K16: Алматы | L16: 1 ось | M16: =IFERROR(__xludf.DUMMYFUNCTION("JOIN("""",VLOOKUP(D16,'для артикула'!$A$2:$B$7,2,0),VLOOKUP(G16,'для артикула'!$A$13:$B$14,2,0),VLOOKUP(E16,'для артикула'!$A$9:$B$11,2,0),VLOOKUP(F16,'для артикула'!$A$17:$B$19,2,0),VLOOKUP(J16,'для артикула'!$A$22:$B$23,2,0),VLOOKUP(H16,'для артикула'!$"&"A$26:$B$30,2,0))"),"002-2013E30Q13-OK") -> 002-2013E30Q13-OK | N16: =IF(ISNUMBER(MATCH(C16, 'Реестр договоров'!$D$2:$D$900, 0)), "Продано", "В наличии") -> Продано
A17: 45617.527 | C17: MX4000002R0001824 | D17: Прицеп 2,0*1,25 м (до 750 кг.) | E17: 50 | F17: R13 | G17: R13 | H17: нет | I17: 45617 | J17: есть | K17: Алматы | L17: 1 ось | M17: =IFERROR(__xludf.DUMMYFUNCTION("JOIN("""",VLOOKUP(D17,'для артикула'!$A$2:$B$7,2,0),VLOOKUP(G17,'для артикула'!$A$13:$B$14,2,0),VLOOKUP(E17,'для артикула'!$A$9:$B$11,2,0),VLOOKUP(F17,'для артикула'!$A$17:$B$19,2,0),VLOOKUP(J17,'для артикула'!$A$22:$B$23,2,0),VLOOKUP(H17,'для артикула'!$"&"A$26:$B$30,2,0))"),"002-2013E50Q13-OK") -> 002-2013E50Q13-OK | N17: =IF(ISNUMBER(MATCH(C17, 'Реестр договоров'!$D$2:$D$900, 0)), "Продано", "В наличии") -> Продано
A18: 45652.487 | C18: MX4000002R0001823 | D18: Прицеп 2,0*1,25 м (до 750 кг.) | E18: 30 | F18: R13 | G18: R13 | H18: нет | I18: 45652 | J18: есть | K18: Алматы | L18: 1 ось | M18: =IFERROR(__xludf.DUMMYFUNCTION("JOIN("""",VLOOKUP(D18,'для артикула'!$A$2:$B$7,2,0),VLOOKUP(G18,'для артикула'!$A$13:$B$14,2,0),VLOOKUP(E18,'для артикула'!$A$9:$B$11,2,0),VLOOKUP(F18,'для артикула'!$A$17:$B$19,2,0),VLOOKUP(J18,'для артикула'!$A$22:$B$23,2,0),VLOOKUP(H18,'для артикула'!$"&"A$26:$B$30,2,0))"),"002-2013E30Q13-OK") -> 002-2013E30Q13-OK | N18: =IF(ISNUMBER(MATCH(C18, 'Реестр договоров'!$D$2:$D$900, 0)), "Продано", "В наличии") -> Продано
A19: 45644.555 | C19: MX4000002R0001822 | D19: Прицеп 2,0*1,25 м (до 750 кг.) | E19: 50 | F19: R13 | G19: R13 | H19: нет | I19: 45629 | J19: есть | K19: Алматы | L19: 1 ось | M19: =IFERROR(__xludf.DUMMYFUNCTION("JOIN("""",VLOOKUP(D19,'для артикула'!$A$2:$B$7,2,0),VLOOKUP(G19,'для артикула'!$A$13:$B$14,2,0),VLOOKUP(E19,'для артикула'!$A$9:$B$11,2,0),VLOOKUP(F19,'для артикула'!$A$17:$B$19,2,0),VLOOKUP(J19,'для артикула'!$A$22:$B$23,2,0),VLOOKUP(H19,'для артикула'!$"&"A$26:$B$30,2,0))"),"002-2013E50Q13-OK") -> 002-2013E50Q13-OK | N19: =IF(ISNUMBER(MATCH(C19, 'Реестр договоров'!$D$2:$D$900, 0)), "Продано", "В наличии") -> Продано
A20: 45617.527 | C20: MX4000002R0001821 | D20: Прицеп 2,0*1,25 м (до 750 кг.) | E20: 50 | F20: R13 | G20: R13 | H20: нет | I20: 45617 | J20: есть | K20: Алматы | L20: 1 ось | M20: =IFERROR(__xludf.DUMMYFUNCTION("JOIN("""",VLOOKUP(D20,'для артикула'!$A$2:$B$7,2,0),VLOOKUP(G20,'для артикула'!$A$13:$B$14,2,0),VLOOKUP(E20,'для артикула'!$A$9:$B$11,2,0),VLOOKUP(F20,'для артикула'!$A$17:$B$19,2,0),VLOOKUP(J20,'для артикула'!$A$22:$B$23,2,0),VLOOKUP(H20,'для артикула'!$"&"A$26:$B$30,2,0))"),"002-2013E50Q13-OK") -> 002-2013E50Q13-OK | N20: =IF(ISNUMBER(MATCH(C20, 'Реестр договоров'!$D$2:$D$900, 0)), "Продано", "В наличии") -> Продано
A21: 45609.514 | C21: MX4000002R0001820 | D21: Прицеп 2,0*1,25 м (до 750 кг.) | E21: 50 | F21: R13 | G21: R13 | H21: нет | I21: 45609 | J21: есть | K21: Алматы | L21: 1 ось | M21: =IFERROR(__xludf.DUMMYFUNCTION("JOIN("""",VLOOKUP(D21,'для артикула'!$A$2:$B$7,2,0),VLOOKUP(G21,'для артикула'!$A$13:$B$14,2,0),VLOOKUP(E21,'для артикула'!$A$9:$B$11,2,0),VLOOKUP(F21,'для артикула'!$A$17:$B$19,2,0),VLOOKUP(J21,'для артикула'!$A$22:$B$23,2,0),VLOOKUP(H21,'для артикула'!$"&"A$26:$B$30,2,0))"),"002-2013E50Q13-OK") -> 002-2013E50Q13-OK | N21: =IF(ISNUMBER(MATCH(C21, 'Реестр договоров'!$D$2:$D$900, 0)), "Продано", "В наличии") -> Продано
A22: 45588.5 | C22: MX4000002R0001817 | D22: Прицеп 2,0*1,25 м (до 750 кг.) | E22: 50 | F22: R13 | G22: R13 | H22: 30 | I22: 45588 | J22: есть | K22: Кокшетау | L22: 1 ось | M22: =IFERROR(__xludf.DUMMYFUNCTION("JOIN("""",VLOOKUP(D22,'для артикула'!$A$2:$B$7,2,0),VLOOKUP(G22,'для артикула'!$A$13:$B$14,2,0),VLOOKUP(E22,'для артикула'!$A$9:$B$11,2,0),VLOOKUP(F22,'для артикула'!$A$17:$B$19,2,0),VLOOKUP(J22,'для артикула'!$A$22:$B$23,2,0),VLOOKUP(H22,'для артикула'!$"&"A$26:$B$30,2,0))"),"002-2013E50Q13-OK30") -> 002-2013E50Q13-OK30 | N22: =IF(ISNUMBER(MATCH(C22, 'Реестр договоров'!$D$2:$D$900, 0)), "Продано", "В наличии") -> Продано
A23: 45583.611 | C23: MX4000002R0001816 | D23: Прицеп 2,0*1,25 м (до 750 кг.) | E23: 50 | F23: R13 | G23: R13 | H23: 30 | I23: 45583 | J23: есть | K23: Астана | L23: 1 ось | M23: =IFERROR(__xludf.DUMMYFUNCTION("JOIN("""",VLOOKUP(D23,'для артикула'!$A$2:$B$7,2,0),VLOOKUP(G23,'для артикула'!$A$13:$B$14,2,0),VLOOKUP(E23,'для артикула'!$A$9:$B$11,2,0),VLOOKUP(F23,'для артикула'!$A$17:$B$19,2,0),VLOOKUP(J23,'для артикула'!$A$22:$B$23,2,0),VLOOKUP(H23,'для артикула'!$"&"A$26:$B$30,2,0))"),"002-2013E50Q13-OK30") -> 002-2013E50Q13-OK30 | N23: =IF(ISNUMBER(MATCH(C23, 'Реестр договоров'!$D$2:$D$900, 0)), "Продано", "В наличии") -> Продано
A24: 45583.608 | C24: MX4000002R0001815 | D24: Прицеп 2,0*1,25 м (до 750 кг.) | E24: 30 | F24: R13 | G24: R13 | H24: 60 | I24: 45583 | J24: есть | K24: Астана | L24: 1 ось | M24: =IFERROR(__xludf.DUMMYFUNCTION("JOIN("""",VLOOKUP(D24,'для артикула'!$A$2:$B$7,2,0),VLOOKUP(G24,'для артикула'!$A$13:$B$14,2,0),VLOOKUP(E24,'для артикула'!$A$9:$B$11,2,0),VLOOKUP(F24,'для артикула'!$A$17:$B$19,2,0),VLOOKUP(J24,'для артикула'!$A$22:$B$23,2,0),VLOOKUP(H24,'для артикула'!$"&"A$26:$B$30,2,0))"),"002-2013E30Q13-OK60") -> 002-2013E30Q13-OK60 | N24: =IF(ISNUMBER(MATCH(C24, 'Реестр договоров'!$D$2:$D$900, 0)), "Продано", "В наличии") -> Продано
A25: 45579.735 | C25: MX4000002R0001813 | D25: Прицеп 2,0*1,25 м (до 750 кг.) | E25: 30 | F25: R13 | G25: R13 | H25: нет | I25: 45579 | J25: есть | K25: Астана | L25: 1 ось | M25: =IFERROR(__xludf.DUMMYFUNCTION("JOIN("""",VLOOKUP(D25,'для артикула'!$A$2:$B$7,2,0),VLOOKUP(G25,'для артикула'!$A$13:$B$14,2,0),VLOOKUP(E25,'для артикула'!$A$9:$B$11,2,0),VLOOKUP(F25,'для артикула'!$A$17:$B$19,2,0),VLOOKUP(J25,'для артикула'!$A$22:$B$23,2,0),VLOOKUP(H25,'для артикула'!$"&"A$26:$B$30,2,0))"),"002-2013E30Q13-OK") -> 002-2013E30Q13-OK | N25: =IF(ISNUMBER(MATCH(C25, 'Реестр договоров'!$D$2:$D$900, 0)), "Продано", "В наличии") -> Продано
A26: 45579.734 | C26: MX4000002R0001812 | D26: Прицеп 2,0*1,25 м (до 750 кг.) | E26: 50 | F26: R13 | G26: R13 | H26: нет | I26: 45579 | J26: есть | K26: Астана | L26: 1 ось | M26: =IFERROR(__xludf.DUMMYFUNCTION("JOIN("""",VLOOKUP(D26,'для артикула'!$A$2:$B$7,2,0),VLOOKUP(G26,'для артикула'!$A$13:$B$14,2,0),VLOOKUP(E26,'для артикула'!$A$9:$B$11,2,0),VLOOKUP(F26,'для артикула'!$A$17:$B$19,2,0),VLOOKUP(J26,'для артикула'!$A$22:$B$23,2,0),VLOOKUP(H26,'для артикула'!$"&"A$26:$B$30,2,0))"),"002-2013E50Q13-OK") -> 002-2013E50Q13-OK | N26: =IF(ISNUMBER(MATCH(C26, 'Реестр договоров'!$D$2:$D$900, 0)), "Продано", "В наличии") -> Продано
A27: 45575.703 | C27: MX4000002R0001811 | D27: Прицеп 2,0*1,25 м (до 750 кг.) | E27: 50 | F27: R13 | G27: R13 | H27: нет | I27: 45575 | J27: есть | K27: Кокшетау | L27: 1 ось | M27: =IFERROR(__xludf.DUMMYFUNCTION("JOIN("""",VLOOKUP(D27,'для артикула'!$A$2:$B$7,2,0),VLOOKUP(G27,'для артикула'!$A$13:$B$14,2,0),VLOOKUP(E27,'для артикула'!$A$9:$B$11,2,0),VLOOKUP(F27,'для артикула'!$A$17:$B$19,2,0),VLOOKUP(J27,'для артикула'!$A$22:$B$23,2,0),VLOOKUP(H27,'для артикула'!$"&"A$26:$B$30,2,0))"),"002-2013E50Q13-OK") -> 002-2013E50Q13-OK | N27: =IF(ISNUMBER(MATCH(C27, 'Реестр договоров'!$D$2:$D$900, 0)), "Продано", "В наличии") -> Продано
A28: 45579.751 | C28: MX4000002R0001804 | D28: Прицеп 2,0*1,25 м (до 750 кг.) | E28: 50 | F28: R13 | G28: R13 | H28: нет | I28: 45579 | J28: есть | K28: Астана | L28: 1 ось | M28: =IFERROR(__xludf.DUMMYFUNCTION("JOIN("""",VLOOKUP(D28,'для артикула'!$A$2:$B$7,2,0),VLOOKUP(G28,'для артикула'!$A$13:$B$14,2,0),VLOOKUP(E28,'для артикула'!$A$9:$B$11,2,0),VLOOKUP(F28,'для артикула'!$A$17:$B$19,2,0),VLOOKUP(J28,'для артикула'!$A$22:$B$23,2,0),VLOOKUP(H28,'для артикула'!$"&"A$26:$B$30,2,0))"),"002-2013E50Q13-OK") -> 002-2013E50Q13-OK | N28: =IF(ISNUMBER(MATCH(C28, 'Реестр договоров'!$D$2:$D$900, 0)), "Продано", "В наличии") -> Продано
A29: 45579.752 | C29: MX4000002R0001803 | D29: Прицеп 2,0*1,25 м (до 750 кг.) | E29: 30 | F29: R13 | G29: R13 | H29: 60 | I29: 45579 | J29: есть | K29: Астана | L29: 1 ось | M29: =IFERROR(__xludf.DUMMYFUNCTION("JOIN("""",VLOOKUP(D29,'для артикула'!$A$2:$B$7,2,0),VLOOKUP(G29,'для артикула'!$A$13:$B$14,2,0),VLOOKUP(E29,'для артикула'!$A$9:$B$11,2,0),VLOOKUP(F29,'для артикула'!$A$17:$B$19,2,0),VLOOKUP(J29,'для артикула'!$A$22:$B$23,2,0),VLOOKUP(H29,'для артикула'!$"&"A$26:$B$30,2,0))"),"002-2013E30Q13-OK60") -> 002-2013E30Q13-OK60 | N29: =IF(ISNUMBER(MATCH(C29, 'Реестр договоров'!$D$2:$D$900, 0)), "Продано", "В наличии") -> Продано
A30: 45568.481 | C30: MX4000002R0001802 | D30: Прицеп 2,0*1,25 м (до 750 кг.) | E30: 50 | F30: R13 | G30: R13 | H30: 30 | I30: 45568 | J30: есть | K30: Кокшетау | L30: 1 ось | M30: =IFERROR(__xludf.DUMMYFUNCTION("JOIN("""",VLOOKUP(D30,'для артикула'!$A$2:$B$7,2,0),VLOOKUP(G30,'для артикула'!$A$13:$B$14,2,0),VLOOKUP(E30,'для артикула'!$A$9:$B$11,2,0),VLOOKUP(F30,'для артикула'!$A$17:$B$19,2,0),VLOOKUP(J30,'для артикула'!$A$22:$B$23,2,0),VLOOKUP(H30,'для артикула'!$"&"A$26:$B$30,2,0))"),"002-2013E50Q13-OK30") -> 002-2013E50Q13-OK30 | N30: =IF(ISNUMBER(MATCH(C30, 'Реестр договоров'!$D$2:$D$900, 0)), "Продано", "В наличии") -> Продано
A31: 45579.746 | C31: MX4000002R0001801 | D31: Прицеп 2,0*1,25 м (до 750 кг.) | E31: 50 | F31: R13 | G31: R13 | H31: 30 | I31: 45579 | J31: есть | K31: Астана | L31: 1 ось | M31: =IFERROR(__xludf.DUMMYFUNCTION("JOIN("""",VLOOKUP(D31,'для артикула'!$A$2:$B$7,2,0),VLOOKUP(G31,'для артикула'!$A$13:$B$14,2,0),VLOOKUP(E31,'для артикула'!$A$9:$B$11,2,0),VLOOKUP(F31,'для артикула'!$A$17:$B$19,2,0),VLOOKUP(J31,'для артикула'!$A$22:$B$23,2,0),VLOOKUP(H31,'для артикула'!$"&"A$26:$B$30,2,0))"),"002-2013E50Q13-OK30") -> 002-2013E50Q13-OK30 | N31: =IF(ISNUMBER(MATCH(C31, 'Реестр договоров'!$D$2:$D$900, 0)), "Продано", "В наличии") -> Продано
A32: 45579.747 | C32: MX4000002R0001800 | D32: Прицеп 2,0*1,25 м (до 750 кг.) | E32: 50 | F32: R15 | G32: R15 | H32: 30 | I32: 45579 | J32: есть | K32: Астана | L32: 1 ось | M32: =IFERROR(__xludf.DUMMYFUNCTION("JOIN("""",VLOOKUP(D32,'для артикула'!$A$2:$B$7,2,0),VLOOKUP(G32,'для артикула'!$A$13:$B$14,2,0),VLOOKUP(E32,'для артикула'!$A$9:$B$11,2,0),VLOOKUP(F32,'для артикула'!$A$17:$B$19,2,0),VLOOKUP(J32,'для артикула'!$A$22:$B$23,2,0),VLOOKUP(H32,'для артикула'!$"&"A$26:$B$30,2,0))"),"002-2013E50Q15-OK30") -> 002-2013E50Q15-OK30 | N32: =IF(ISNUMBER(MATCH(C32, 'Реестр договоров'!$D$2:$D$900, 0)), "Продано", "В наличии") -> Продано
A33: 45612.467 | C33: MX4000002R0001790 | D33: Прицеп 2,0*1,25 м (до 750 кг.) | E33: 50 | F33: R13 | G33: R13 | H33: нет | I33: 45612 | J33: есть | K33: Алматы | L33: 1 ось | M33: =IFERROR(__xludf.DUMMYFUNCTION("JOIN("""",VLOOKUP(D33,'для артикула'!$A$2:$B$7,2,0),VLOOKUP(G33,'для артикула'!$A$13:$B$14,2,0),VLOOKUP(E33,'для артикула'!$A$9:$B$11,2,0),VLOOKUP(F33,'для артикула'!$A$17:$B$19,2,0),VLOOKUP(J33,'для артикула'!$A$22:$B$23,2,0),VLOOKUP(H33,'для артикула'!$"&"A$26:$B$30,2,0))"),"002-2013E50Q13-OK") -> 002-2013E50Q13-OK | N33: =IF(ISNUMBER(MATCH(C33, 'Реестр договоров'!$D$2:$D$900, 0)), "Продано", "В наличии") -> Продано
A34: 45609.45 | C34: MX4000002R0001789 | D34: Прицеп 2,0*1,25 м (до 750 кг.) | E34: 50 | F34: R13 | G34: R13 | H34: нет | I34: 45609 | J34: есть | K34: Алматы | L34: 1 ось | M34: =IFERROR(__xludf.DUMMYFUNCTION("JOIN("""",VLOOKUP(D34,'для артикула'!$A$2:$B$7,2,0),VLOOKUP(G34,'для артикула'!$A$13:$B$14,2,0),VLOOKUP(E34,'для артикула'!$A$9:$B$11,2,0),VLOOKUP(F34,'для артикула'!$A$17:$B$19,2,0),VLOOKUP(J34,'для артикула'!$A$22:$B$23,2,0),VLOOKUP(H34,'для артикула'!$"&"A$26:$B$30,2,0))"),"002-2013E50Q13-OK") -> 002-2013E50Q13-OK | N34: =IF(ISNUMBER(MATCH(C34, 'Реестр договоров'!$D$2:$D$900, 0)), "Продано", "В наличии") -> Продано
A35: 45606.532 | C35: MX4000002R0001788 | D35: Прицеп 2,0*1,25 м (до 750 кг.) | E35: 30 | F35: R13 | G35: R13 | H35: нет | I35: 45606 | J35: есть | K35: Алматы | L35: 1 ось | M35: =IFERROR(__xludf.DUMMYFUNCTION("JOIN("""",VLOOKUP(D35,'для артикула'!$A$2:$B$7,2,0),VLOOKUP(G35,'для артикула'!$A$13:$B$14,2,0),VLOOKUP(E35,'для артикула'!$A$9:$B$11,2,0),VLOOKUP(F35,'для артикула'!$A$17:$B$19,2,0),VLOOKUP(J35,'для артикула'!$A$22:$B$23,2,0),VLOOKUP(H35,'для артикула'!$"&"A$26:$B$30,2,0))"),"002-2013E30Q13-OK") -> 002-2013E30Q13-OK | N35: =IF(ISNUMBER(MATCH(C35, 'Реестр договоров'!$D$2:$D$900, 0)), "Продано", "В наличии") -> Продано
A36: 45576.64 | C36: MX4000002R0001787 | D36: Прицеп 2,0*1,25 м (до 750 кг.) | E36: 50 | F36: R13 | G36: R13 | H36: нет | I36: 45576 | J36: есть | K36: Алматы | L36: 1 ось | M36: =IFERROR(__xludf.DUMMYFUNCTION("JOIN("""",VLOOKUP(D36,'для артикула'!$A$2:$B$7,2,0),VLOOKUP(G36,'для артикула'!$A$13:$B$14,2,0),VLOOKUP(E36,'для артикула'!$A$9:$B$11,2,0),VLOOKUP(F36,'для артикула'!$A$17:$B$19,2,0),VLOOKUP(J36,'для артикула'!$A$22:$B$23,2,0),VLOOKUP(H36,'для артикула'!$"&"A$26:$B$30,2,0))"),"002-2013E50Q13-OK") -> 002-2013E50Q13-OK | N36: =IF(ISNUMBER(MATCH(C36, 'Реестр договоров'!$D$2:$D$900, 0)), "Продано", "В наличии") -> Продано
A37: 45600.584 | C37: MX4000002R0001786 | D37: Прицеп 2,0*1,25 м (до 750 кг.) | E37: 50 | F37: R13 | G37: R13 | H37: нет | I37: 45600 | J37: есть | K37: Алматы | L37: 1 ось | M37: =IFERROR(__xludf.DUMMYFUNCTION("JOIN("""",VLOOKUP(D37,'для артикула'!$A$2:$B$7,2,0),VLOOKUP(G37,'для артикула'!$A$13:$B$14,2,0),VLOOKUP(E37,'для артикула'!$A$9:$B$11,2,0),VLOOKUP(F37,'для артикула'!$A$17:$B$19,2,0),VLOOKUP(J37,'для артикула'!$A$22:$B$23,2,0),VLOOKUP(H37,'для артикула'!$"&"A$26:$B$30,2,0))"),"002-2013E50Q13-OK") -> 002-2013E50Q13-OK | N37: =IF(ISNUMBER(MATCH(C37, 'Реестр договоров'!$D$2:$D$900, 0)), "Продано", "В наличии") -> Продано
A38: 45601.76 | C38: MX4000002R0001785 | D38: Прицеп 2,0*1,25 м (до 750 кг.) | E38: 50 | F38: R13 | G38: R13 | H38: нет | I38: 45600 | J38: есть | K38: Алматы | L38: 1 ось | M38: =IFERROR(__xludf.DUMMYFUNCTION("JOIN("""",VLOOKUP(D38,'для артикула'!$A$2:$B$7,2,0),VLOOKUP(G38,'для артикула'!$A$13:$B$14,2,0),VLOOKUP(E38,'для артикула'!$A$9:$B$11,2,0),VLOOKUP(F38,'для артикула'!$A$17:$B$19,2,0),VLOOKUP(J38,'для артикула'!$A$22:$B$23,2,0),VLOOKUP(H38,'для артикула'!$"&"A$26:$B$30,2,0))"),"002-2013E50Q13-OK") -> 002-2013E50Q13-OK | N38: =IF(ISNUMBER(MATCH(C38, 'Реестр договоров'!$D$2:$D$900, 0)), "Продано", "В наличии") -> Продано
A39: 45606.499 | C39: MX4000002R0001784 | D39: Прицеп 2,0*1,25 м (до 750 кг.) | E39: 30 | F39: R13 | G39: R13 | H39: нет | I39: 45606 | J39: есть | K39: Алматы | L39: 1 ось | M39: =IFERROR(__xludf.DUMMYFUNCTION("JOIN("""",VLOOKUP(D39,'для артикула'!$A$2:$B$7,2,0),VLOOKUP(G39,'для артикула'!$A$13:$B$14,2,0),VLOOKUP(E39,'для артикула'!$A$9:$B$11,2,0),VLOOKUP(F39,'для артикула'!$A$17:$B$19,2,0),VLOOKUP(J39,'для артикула'!$A$22:$B$23,2,0),VLOOKUP(H39,'для артикула'!$"&"A$26:$B$30,2,0))"),"002-2013E30Q13-OK") -> 002-2013E30Q13-OK | N39: =IF(ISNUMBER(MATCH(C39, 'Реестр договоров'!$D$2:$D$900, 0)), "Продано", "В наличии") -> Продано
A40: 45583.709 | C40: MX4000002R0001783 | D40: Прицеп 2,0*1,25 м (до 750 кг.) | E40: 50 | F40: R13 | G40: R13 | H40: нет | I40: 45583 | J40: есть | K40: Алматы | L40: 1 ось | M40: =IFERROR(__xludf.DUMMYFUNCTION("JOIN("""",VLOOKUP(D40,'для артикула'!$A$2:$B$7,2,0),VLOOKUP(G40,'для артикула'!$A$13:$B$14,2,0),VLOOKUP(E40,'для артикула'!$A$9:$B$11,2,0),VLOOKUP(F40,'для артикула'!$A$17:$B$19,2,0),VLOOKUP(J40,'для артикула'!$A$22:$B$23,2,0),VLOOKUP(H40,'для артикула'!$"&"A$26:$B$30,2,0))"),"002-2013E50Q13-OK") -> 002-2013E50Q13-OK | N40: =IF(ISNUMBER(MATCH(C40, 'Реестр договоров'!$D$2:$D$900, 0)), "Продано", "В наличии") -> Продано
...

Sheet Сводная таблица ФЛ
B1: дата | C1: фамилия | D1: Имя | E1: Отчество | F1: удостоверение № | G1: дата выдачи удостоверения | H1: кем выдано | I1: ИИН | J1: Адрес проживания | K1: Телефон | L1: VIN | M1: Артикул | N1: прицеп | O1: Количество осей | P1: год выпуска прицепа | Q1: габариты | R1: размеры кузова | S1: ОТТС | T1: цена | U1: склад
A2: 1161 | B2: =VLOOKUP(A2,'Реестр договоров'!$A$2:$D$149,2,0) -> 45447 | C2: =VLOOKUP(A2,Реестр_Договоров,3,0) -> Белоногова | D2: =VLOOKUP(C2,Покупатели,2,0) -> Алена | E2: =VLOOKUP(C2,Покупатели,3,0) -> Андреевна | F2: =VLOOKUP(C2,Покупатели,4,0) -> 040645875 | G2: =VLOOKUP(F2,Покупатели!$F$2:$N$762,2,0) -> 42627 | H2: =VLOOKUP(F2,Покупатели!$F$2:$N$762,3,0) -> МВД РК | I2: =VLOOKUP(C2,Покупатели!$C$2:$M$805,7,0) -> 890311400050 | J2: =IFERROR(__xludf.DUMMYFUNCTION("JOIN("" "", VLOOKUP(C2,Покупатели,8,0),VLOOKUP(C2,Покупатели,9,0),VLOOKUP(C2,Покупатели,10,0),VLOOKUP(C2,Покупатели,11,0))"),"г.Алматы ") -> г.Алматы | K2: =VLOOKUP(C2,Покупатели,12,0) -> 87764755555 | L2: =VLOOKUP(A2,Реестр_Договоров,4,0) -> MX4000002R0001522 | M2: 002-2313E30Q13-OK | N2: Прицеп 2,3*1,25 м (до 750 кг.) | O2: =VLOOKUP(L2,ПРИЦЕПЫ,10,0) -> 1 ось | P2: =YEAR(VLOOKUP(L2,ПРИЦЕПЫ,7,0)) -> 2024 | Q2: 3450*1700*900 | R2: 2300*1250*300 | S2: =VLOOKUP(O2,ОТТС!$A$2:$B$3,2,0) -> ТС KZ Е-KZ.0317.00251 от 28.02.2023 | T2: 320000 | U2: =VLOOKUP(L2,ПРИЦЕПЫ,9,0) -> Алматы
A3: 1162 | B3: =VLOOKUP(A3,'Реестр договоров'!$A$2:$D$169,2,0) -> 45449 | C3: =VLOOKUP(A3,Реестр_Договоров,3,0) -> Рахманов | D3: =VLOOKUP(C3,Покупатели,2,0) -> Мурат | E3: =VLOOKUP(C3,Покупатели,3,0) -> Халмуратович | F3: =VLOOKUP(C3,Покупатели,4,0) -> 044798593 | G3: =VLOOKUP(F3,Покупатели!$F$2:$N$762,2,0) -> 43531 | H3: =VLOOKUP(F3,Покупатели!$F$2:$N$762,3,0) -> МВД РК | I3: =VLOOKUP(C3,Покупатели!$C$2:$M$805,7,0) -> 881115302551 | J3: =IFERROR(__xludf.DUMMYFUNCTION("JOIN("" "", VLOOKUP(C3,Покупатели,8,0),VLOOKUP(C3,Покупатели,9,0),VLOOKUP(C3,Покупатели,10,0),VLOOKUP(C3,Покупатели,11,0))"),"Талгарский район, пос.Бесагаш, ул.Бейбитшилик 30 Бейбитшилик 30") -> Талгарский район, пос.Бесагаш, ул.Бейбитшилик 30 Бейбитшилик 30 | K3: =VLOOKUP(C3,Покупатели,12,0) -> 87071133370 | L3: =VLOOKUP(A3,Реестр_Договоров,4,0) -> MX4000002R0001502 | M3: =VLOOKUP(L3,ПРИЦЕПЫ,11,0) -> 002-2513E50Q13-OK | N3: =VLOOKUP(L3,ПРИЦЕПЫ,2,0) -> Прицеп 2,5*1,25 м (до 750 кг.) | O3: =VLOOKUP(L3,ПРИЦЕПЫ,10,0) -> 1 ось | P3: =YEAR(VLOOKUP(L3,ПРИЦЕПЫ,7,0)) -> 2024 | Q3: =VLOOKUP(M3,матрица,16,0) -> 3650*1700*1070 | R3: =VLOOKUP(M3,матрица,17,0) -> 2500*1250*500 | S3: =VLOOKUP(O3,ОТТС!$A$2:$B$3,2,0) -> ТС KZ Е-KZ.0317.00251 от 28.02.2023 | T3: 410000 | U3: =VLOOKUP(L3,ПРИЦЕПЫ,9,0) -> Алматы
A4: 1163 | B4: =VLOOKUP(A4,'Реестр договоров'!$A$2:$D$506,2,0) -> 45450 | C4: =VLOOKUP(A4,Реестр_Договоров,3,0) -> Кулиева | D4: =VLOOKUP(C4,Покупатели,2,0) -> Ёсма | E4: =VLOOKUP(C4,Покупатели,3,0) -> Ахмедовна | F4: =VLOOKUP(C4,Покупатели,4,0) -> 045683377 | G4: =VLOOKUP(F4,Покупатели!$F$2:$N$762,2,0) -> 43852 | H4: =VLOOKUP(F4,Покупатели!$F$2:$N$762,3,0) -> МВД РК | I4: =VLOOKUP(C4,Покупатели!$C$2:$M$805,7,0) -> 841220400347 | J4: =IFERROR(__xludf.DUMMYFUNCTION("JOIN("" "", VLOOKUP(C4,Покупатели,8,0),VLOOKUP(C4,Покупатели,9,0),VLOOKUP(C4,Покупатели,10,0),VLOOKUP(C4,Покупатели,11,0))"),"Алматинская область Алматы _____ ______") -> Алматинская область Алматы _____ ______ | K4: =VLOOKUP(C4,Покупатели,12,0) -> 87476056411 | L4: =VLOOKUP(A4,Реестр_Договоров,4,0) -> MX4000002R0001511 | M4: =VLOOKUP(L4,ПРИЦЕПЫ,11,0) -> 002-2513E30Q13-OK | N4: =VLOOKUP(L4,ПРИЦЕПЫ,2,0) -> Прицеп 2,5*1,25 м (до 750 кг.) | O4: =VLOOKUP(L4,ПРИЦЕПЫ,10,0) -> 1 ось | P4: =YEAR(VLOOKUP(L4,ПРИЦЕПЫ,7,0)) -> 2024 | Q4: =VLOOKUP(M4,матрица,16,0) -> 3650*1700*900 | R4: =VLOOKUP(M4,матрица,17,0) -> 2500*1250*300 | S4: =VLOOKUP(O4,ОТТС!$A$2:$B$3,2,0) -> ТС KZ Е-KZ.0317.00251 от 28.02.2023 | T4: 320000 | U4: =VLOOKUP(L4,ПРИЦЕПЫ,9,0) -> Алматы
A5: 1164 | B5: =VLOOKUP(A5,'Реестр договоров'!$A$2:$D$89,2,0) -> 45451 | C5: =VLOOKUP(A5,Реестр_Договоров,3,0) -> Петрик | D5: =VLOOKUP(C5,Покупатели,2,0) -> Владимир | E5: =VLOOKUP(C5,Покупатели,3,0) -> Ярославович | F5: =VLOOKUP(C5,Покупатели,4,0) -> 050163641 | G5: =VLOOKUP(F5,Покупатели!$F$2:$N$762,2,0) -> 44614 | H5: =VLOOKUP(F5,Покупатели!$F$2:$N$762,3,0) -> МВД РК | I5: =VLOOKUP(C5,Покупатели!$C$2:$M$805,7,0) -> 870213300256 | J5: =IFERROR(__xludf.DUMMYFUNCTION("JOIN("" "", VLOOKUP(C5,Покупатели,8,0),VLOOKUP(C5,Покупатели,9,0),VLOOKUP(C5,Покупатели,10,0),VLOOKUP(C5,Покупатели,11,0))"),"Алматинская Алматы неизвестно неизвестно") -> Алматинская Алматы неизвестно неизвестно | K5: =VLOOKUP(C5,Покупатели,12,0) -> 87019294069 | L5: =VLOOKUP(A5,Реестр_Договоров,4,0) -> MX4000002R0001518 | M5: =VLOOKUP(L5,ПРИЦЕПЫ,11,0) -> 002-2513E50Q13 | N5: =VLOOKUP(L5,ПРИЦЕПЫ,2,0) -> Прицеп 2,5*1,25 м (до 750 кг.) | O5: =VLOOKUP(L5,ПРИЦЕПЫ,10,0) -> 1 ось | P5: =YEAR(VLOOKUP(L5,ПРИЦЕПЫ,7,0)) -> 2024 | Q5: =VLOOKUP(M5,матрица,16,0) -> 3650*1700*1070 | R5: =VLOOKUP(M5,матрица,17,0) -> 2500*1250*500 | S5: =VLOOKUP(O5,ОТТС!$A$2:$B$3,2,0) -> ТС KZ Е-KZ.0317.00251 от 28.02.2023 | T5: 460000 | U5: =VLOOKUP(L5,ПРИЦЕПЫ,9,0) -> Алматы
A6: 1165 | B6: =VLOOKUP(A6,'Реестр договоров'!$A$2:$D$506,2,0) -> 45451 | C6: =VLOOKUP(A6,Реестр_Договоров,3,0) -> Ребенков | D6: =VLOOKUP(C6,Покупатели,2,0) -> Вячеслав | E6: =VLOOKUP(C6,Покупатели,3,0) -> Сергеевич | F6: =VLOOKUP(C6,Покупатели,4,0) -> 046534151 | G6: =VLOOKUP(F6,Покупатели!$F$2:$N$762,2,0) -> 44013 | H6: =VLOOKUP(F6,Покупатели!$F$2:$N$762,3,0) -> МВД РК | I6: =VLOOKUP(C6,Покупатели!$C$2:$M$805,7,0) -> 850210303171 | J6: =IFERROR(__xludf.DUMMYFUNCTION("JOIN("" "", VLOOKUP(C6,Покупатели,8,0),VLOOKUP(C6,Покупатели,9,0),VLOOKUP(C6,Покупатели,10,0),VLOOKUP(C6,Покупатели,11,0))"),"Алматинская Алматы неизвестно неизвестно") -> Алматинская Алматы неизвестно неизвестно | K6: =VLOOKUP(C6,Покупатели,12,0) -> 87770334835 | L6: =VLOOKUP(A6,Реестр_Договоров,4,0) -> MX4000002R0001573 | M6: =VLOOKUP(L6,ПРИЦЕПЫ,11,0) -> 002-2013E30Q13-OK | N6: =VLOOKUP(L6,ПРИЦЕПЫ,2,0) -> Прицеп 2,0*1,25 м (до 750 кг.) | O6: =VLOOKUP(L6,ПРИЦЕПЫ,10,0) -> 1 ось | P6: =YEAR(VLOOKUP(L6,ПРИЦЕПЫ,7,0)) -> 2024 | Q6: =VLOOKUP(M6,матрица,16,0) -> 3150*1700*900 | R6: =VLOOKUP(M6,матрица,17,0) -> 2000*1250*300 | S6: =VLOOKUP(O6,ОТТС!$A$2:$B$3,2,0) -> ТС KZ Е-KZ.0317.00251 от 28.02.2023 | T6: 350000 | U6: =VLOOKUP(L6,ПРИЦЕПЫ,9,0) -> Алматы
A7: 1166 | B7: =VLOOKUP(A7,'Реестр договоров'!$A$2:$D$506,2,0) -> 45451 | C7: =VLOOKUP(A7,Реестр_Договоров,3,0) -> Темирбаев | D7: =VLOOKUP(C7,Покупатели,2,0) -> Талгат | E7: =VLOOKUP(C7,Покупатели,3,0) -> Ахванович | F7: =VLOOKUP(C7,Покупатели,4,0) -> 045893821 | G7: =VLOOKUP(F7,Покупатели!$F$2:$N$762,2,0) -> 43882 | H7: =VLOOKUP(F7,Покупатели!$F$2:$N$762,3,0) -> МВД РК | I7: =VLOOKUP(C7,Покупатели!$C$2:$M$805,7,0) -> 720613302306 | J7: =IFERROR(__xludf.DUMMYFUNCTION("JOIN("" "", VLOOKUP(C7,Покупатели,8,0),VLOOKUP(C7,Покупатели,9,0),VLOOKUP(C7,Покупатели,10,0),VLOOKUP(C7,Покупатели,11,0))"),"Алматинская Алматы ____ ____") -> Алматинская Алматы ____ ____ | K7: =VLOOKUP(C7,Покупатели,12,0) -> 87754573372 | L7: =VLOOKUP(A7,Реестр_Договоров,4,0) -> MX4000002R0001455 | M7: =VLOOKUP(L7,ПРИЦЕПЫ,11,0) -> 002-2013E50Q13-OK | N7: =VLOOKUP(L7,ПРИЦЕПЫ,2,0) -> Прицеп 2,0*1,25 м (до 750 кг.) | O7: =VLOOKUP(L7,ПРИЦЕПЫ,10,0) -> 1 ось | P7: =YEAR(VLOOKUP(L7,ПРИЦЕПЫ,7,0)) -> 2024 | Q7: =VLOOKUP(M7,матрица,16,0) -> 3150*1700*1070 | R7: =VLOOKUP(M7,матрица,17,0) -> 2000*1250*500 | S7: =VLOOKUP(O7,ОТТС!$A$2:$B$3,2,0) -> ТС KZ Е-KZ.0317.00251 от 28.02.2023 | T7: 410000 | U7: =VLOOKUP(L7,ПРИЦЕПЫ,9,0) -> Алматы
A8: 1167 | B8: =VLOOKUP(A8,'Реестр договоров'!$A$2:$D$55,2,0) -> 45453 | C8: =VLOOKUP(A8,Реестр_Договоров,3,0) -> Доспергенов | D8: =VLOOKUP(C8,Покупатели,2,0) -> Акылбек | E8: =VLOOKUP(C8,Покупатели,3,0) -> Казисович | F8: =VLOOKUP(C8,Покупатели,4,0) -> 047229978 | G8: =VLOOKUP(F8,Покупатели!$F$2:$N$762,2,0) -> 43844 | H8: =VLOOKUP(F8,Покупатели!$F$2:$N$762,3,0) -> МВД РК | I8: =VLOOKUP(C8,Покупатели!$C$2:$M$805,7,0) -> 680601300126 | J8: =IFERROR(__xludf.DUMMYFUNCTION("JOIN("" "", VLOOKUP(C8,Покупатели,8,0),VLOOKUP(C8,Покупатели,9,0),VLOOKUP(C8,Покупатели,10,0),VLOOKUP(C8,Покупатели,11,0))"),"Акмолинская область Район Биржан Сал, г.Степняк ул.Сейфуллина 31") -> Акмолинская область Район Биржан Сал, г.Степняк ул.Сейфуллина 31 | K8: =VLOOKUP(C8,Покупатели,12,0) -> 87752586301 | L8: =VLOOKUP(A8,Реестр_Договоров,4,0) -> MX4000002R0001719 | M8: =VLOOKUP(L8,ПРИЦЕПЫ,11,0) -> 002-2515E50Q13-OK60 | N8: =VLOOKUP(L8,ПРИЦЕПЫ,2,0) -> Прицеп 2,5*1,5 м (до 750 кг.) | O8: =VLOOKUP(L8,ПРИЦЕПЫ,10,0) -> 1 ось | P8: =YEAR(VLOOKUP(L8,ПРИЦЕПЫ,7,0)) -> 2024 | Q8: =VLOOKUP(M8,матрица,16,0) -> #N/A | R8: =VLOOKUP(M8,матрица,17,0) -> #N/A | S8: =VLOOKUP(O8,ОТТС!$A$2:$B$3,2,0) -> ТС KZ Е-KZ.0317.00251 от 28.02.2023 | T8: 430000 | U8: =VLOOKUP(L8,ПРИЦЕПЫ,9,0) -> Кокшетау
A9: 1168 | B9: =VLOOKUP(A9,'Реестр договоров'!$A$2:$D$149,2,0) -> 45451 | C9: =VLOOKUP(A9,Реестр_Договоров,3,0) -> Касымов | D9: =VLOOKUP(C9,Покупатели,2,0) -> Серик | E9: =VLOOKUP(C9,Покупатели,3,0) -> Кушенович | F9: =VLOOKUP(C9,Покупатели,4,0) -> 019325596 | G9: =VLOOKUP(F9,Покупатели!$F$2:$N$762,2,0) -> 38940 | H9: =VLOOKUP(F9,Покупатели!$F$2:$N$762,3,0) -> МЮ РК | I9: =VLOOKUP(C9,Покупатели!$C$2:$M$805,7,0) -> 610801350197 | J9: =IFERROR(__xludf.DUMMYFUNCTION("JOIN("" "", VLOOKUP(C9,Покупатели,8,0),VLOOKUP(C9,Покупатели,9,0),VLOOKUP(C9,Покупатели,10,0),VLOOKUP(C9,Покупатели,11,0))"),"Акмолинская область г.Макинск Ул.Луговая 48") -> Акмолинская область г.Макинск Ул.Луговая 48 | K9: =VLOOKUP(C9,Покупатели,12,0) -> 87752523752 | L9: =VLOOKUP(A9,Реестр_Договоров,4,0) -> MX4000002R0001642 | M9: =VLOOKUP(L9,ПРИЦЕПЫ,11,0) -> 002-2513E50Q13-OK60 | N9: =VLOOKUP(L9,ПРИЦЕПЫ,2,0) -> Прицеп 2,5*1,25 м (до 750 кг.) | O9: =VLOOKUP(L9,ПРИЦЕПЫ,10,0) -> 1 ось | P9: =YEAR(VLOOKUP(L9,ПРИЦЕПЫ,7,0)) -> 2024 | Q9: =VLOOKUP(M9,матрица,16,0) -> 3650*1700*1070 | R9: =VLOOKUP(M9,матрица,17,0) -> 2500*1250*500 | S9: =VLOOKUP(O9,ОТТС!$A$2:$B$3,2,0) -> ТС KZ Е-KZ.0317.00251 от 28.02.2023 | T9: 450000 | U9: =VLOOKUP(L9,ПРИЦЕПЫ,9,0) -> Астана
A10: 1169 | B10: =VLOOKUP(A10,'Реестр договоров'!$A$2:$D$100,2,0) -> 45455 | C10: =VLOOKUP(A10,Реестр_Договоров,3,0) -> Сулейменов 2 | D10: =VLOOKUP(C10,Покупатели,2,0) -> Ерсин | E10: =VLOOKUP(C10,Покупатели,3,0) -> Султанович | F10: =VLOOKUP(C10,Покупатели,4,0) -> 048516590 | G10: =VLOOKUP(F10,Покупатели!$F$2:$N$762,2,0) -> 44057 | H10: =VLOOKUP(F10,Покупатели!$F$2:$N$762,3,0) -> МВД РК | I10: =VLOOKUP(C10,Покупатели!$C$2:$M$805,7,0) -> 640617350370 | J10: =IFERROR(__xludf.DUMMYFUNCTION("JOIN("" "", VLOOKUP(C10,Покупатели,8,0),VLOOKUP(C10,Покупатели,9,0),VLOOKUP(C10,Покупатели,10,0),VLOOKUP(C10,Покупатели,11,0))"),"Костанайская область г.Аркалык ул.Ашу тасты, 60 лет казахстан ") -> Костанайская область г.Аркалык ул.Ашу тасты, 60 лет казахстан | K10: =VLOOKUP(C10,Покупатели,12,0) -> 87783266344 | L10: =VLOOKUP(A10,Реестр_Договоров,4,0) -> MX4000002R0001659 | M10: =VLOOKUP(L10,ПРИЦЕПЫ,11,0) -> 002-2013E50Q13-OK | N10: =VLOOKUP(L10,ПРИЦЕПЫ,2,0) -> Прицеп 2,0*1,25 м (до 750 кг.) | O10: =VLOOKUP(L10,ПРИЦЕПЫ,10,0) -> 1 ось | P10: =YEAR(VLOOKUP(L10,ПРИЦЕПЫ,7,0)) -> 2024 | Q10: =VLOOKUP(M10,матрица,16,0) -> 3150*1700*1070 | R10: =VLOOKUP(M10,матрица,17,0) -> 2000*1250*500 | S10: =VLOOKUP(O10,ОТТС!$A$2:$B$3,2,0) -> ТС KZ Е-KZ.0317.00251 от 28.02.2023 | T10: 340000 | U10: =VLOOKUP(L10,ПРИЦЕПЫ,9,0) -> Астана
A11: 1170 | B11: =VLOOKUP(A11,'Реестр договоров'!$A$2:$D$80,2,0) -> 45460 | C11: =VLOOKUP(A11,Реестр_Договоров,3,0) -> Курбанова | D11: =VLOOKUP(C11,Покупатели,2,0) -> Лязиза | E11: =VLOOKUP(C11,Покупатели,3,0) -> Зерупжановна | F11: =VLOOKUP(C11,Покупатели,4,0) -> 036786727 | G11: =VLOOKUP(F11,Покупатели!$F$2:$N$762,2,0) -> 41851 | H11: =VLOOKUP(F11,Покупатели!$F$2:$N$762,3,0) -> МВД РК | I11: =VLOOKUP(C11,Покупатели!$C$2:$M$805,7,0) -> 930829401203 | J11: =IFERROR(__xludf.DUMMYFUNCTION("JOIN("" "", VLOOKUP(C11,Покупатели,8,0),VLOOKUP(C11,Покупатели,9,0),VLOOKUP(C11,Покупатели,10,0),VLOOKUP(C11,Покупатели,11,0))"),"Алматинская область Г.Талгар Ул.Рыскулова Д.104") -> Алматинская область Г.Талгар Ул.Рыскулова Д.104 | K11: =VLOOKUP(C11,Покупатели,12,0) -> 87475777615 | L11: =VLOOKUP(A11,Реестр_Договоров,4,0) -> MX4000002R0001508 | M11: =VLOOKUP(L11,ПРИЦЕПЫ,11,0) -> 002-2513E30Q13-OK | N11: =VLOOKUP(L11,ПРИЦЕПЫ,2,0) -> Прицеп 2,5*1,25 м (до 750 кг.) | O11: =VLOOKUP(L11,ПРИЦЕПЫ,10,0) -> 1 ось | P11: =YEAR(VLOOKUP(L11,ПРИЦЕПЫ,7,0)) -> 2024 | Q11: =VLOOKUP(M11,матрица,16,0) -> 3650*1700*900 | R11: =VLOOKUP(M11,матрица,17,0) -> 2500*1250*300 | S11: =VLOOKUP(O11,ОТТС!$A$2:$B$3,2,0) -> ТС KZ Е-KZ.0317.00251 от 28.02.2023 | T11: 320000 | U11: =VLOOKUP(L11,ПРИЦЕПЫ,9,0) -> Алматы
A12: 1171 | B12: =VLOOKUP(A12,'Реестр договоров'!$A$2:$D$55,2,0) -> 45461 | C12: =VLOOKUP(A12,Реестр_Договоров,3,0) -> Абайқызы | D12: =VLOOKUP(C12,Покупатели,2,0) -> Нұргүл | E12: =VLOOKUP(C12,Покупатели,3,0) -> 0 | F12: =VLOOKUP(C12,Покупатели,4,0) -> 052028739 | G12: =VLOOKUP(F12,Покупатели!$F$2:$N$762,2,0) -> 44875 | H12: =VLOOKUP(F12,Покупатели!$F$2:$N$762,3,0) -> ҚР ІІМ | I12: =VLOOKUP(C12,Покупатели!$C$2:$M$805,7,0) -> 871112400513 | J12: =IFERROR(__xludf.DUMMYFUNCTION("JOIN("" "", VLOOKUP(C12,Покупатели,8,0),VLOOKUP(C12,Покупатели,9,0),VLOOKUP(C12,Покупатели,10,0),VLOOKUP(C12,Покупатели,11,0))"),"Алматинская область Илийский район, пос.Караой Шугыла 5") -> Алматинская область Илийский район, пос.Караой Шугыла 5 | K12: =VLOOKUP(C12,Покупатели,12,0) -> 87079209555 | L12: =VLOOKUP(A12,Реестр_Договоров,4,0) -> MX4000002R0001517 | M12: =VLOOKUP(L12,ПРИЦЕПЫ,11,0) -> 002-2513E50Q13-OK | N12: =VLOOKUP(L12,ПРИЦЕПЫ,2,0) -> Прицеп 2,5*1,25 м (до 750 кг.) | O12: =VLOOKUP(L12,ПРИЦЕПЫ,10,0) -> 1 ось | P12: =YEAR(VLOOKUP(L12,ПРИЦЕПЫ,7,0)) -> 2024 | Q12: =VLOOKUP(M12,матрица,16,0) -> 3650*1700*1070 | R12: =VLOOKUP(M12,матрица,17,0) -> 2500*1250*500 | S12: =VLOOKUP(O12,ОТТС!$A$2:$B$3,2,0) -> ТС KZ Е-KZ.0317.00251 от 28.02.2023 | T12: 380000 | U12: =VLOOKUP(L12,ПРИЦЕПЫ,9,0) -> Алматы
A13: 1172 | B13: =VLOOKUP(A13,'Реестр договоров'!$A$2:$D$80,2,0) -> 45461 | C13: =VLOOKUP(A13,Реестр_Договоров,3,0) -> Меньшиков | D13: =VLOOKUP(C13,Покупатели,2,0) -> Андрей | E13: =VLOOKUP(C13,Покупатели,3,0) -> Геннадьевич | F13: =VLOOKUP(C13,Покупатели,4,0) -> б/н | G13: =VLOOKUP(F13,Покупатели!$F$2:$N$762,2,0) -> 45461 | H13: =VLOOKUP(F13,Покупатели!$F$2:$N$762,3,0) -> МВД РК | I13: =VLOOKUP(C13,Покупатели!$C$2:$M$805,7,0) -> 911205300562 | J13: =IFERROR(__xludf.DUMMYFUNCTION("JOIN("" "", VLOOKUP(C13,Покупатели,8,0),VLOOKUP(C13,Покупатели,9,0),VLOOKUP(C13,Покупатели,10,0),VLOOKUP(C13,Покупатели,11,0))"),"Алматинская область Талдыкурган нет нет") -> Алматинская область Талдыкурган нет нет | K13: =VLOOKUP(C13,Покупатели,12,0) -> нет | L13: =VLOOKUP(A13,Реестр_Договоров,4,0) -> MX4000002R0001538 | M13: =VLOOKUP(L13,ПРИЦЕПЫ,11,0) -> 002-2013E30Q13-OK | N13: =VLOOKUP(L13,ПРИЦЕПЫ,2,0) -> Прицеп 2,0*1,25 м (до 750 кг.) | O13: =VLOOKUP(L13,ПРИЦЕПЫ,10,0) -> 1 ось | P13: =YEAR(VLOOKUP(L13,ПРИЦЕПЫ,7,0)) -> 2024 | Q13: =VLOOKUP(M13,матрица,16,0) -> 3150*1700*900 | R13: =VLOOKUP(M13,матрица,17,0) -> 2000*1250*300 | S13: =VLOOKUP(O13,ОТТС!$A$2:$B$3,2,0) -> ТС KZ Е-KZ.0317.00251 от 28.02.2023 | T13: 380000 | U13: =VLOOKUP(L13,ПРИЦЕПЫ,9,0) -> Алматы
A14: 1173 | B14: =VLOOKUP(A14,'Реестр договоров'!$A$2:$D$120,2,0) -> 45462 | C14: =VLOOKUP(A14,Реестр_Договоров,3,0) -> Билочук | D14: =VLOOKUP(C14,Покупатели,2,0) -> Игорь | E14: =VLOOKUP(C14,Покупатели,3,0) -> Владимирович | F14: =VLOOKUP(C14,Покупатели,4,0) -> 042054030 | G14: =VLOOKUP(F14,Покупатели!$F$2:$N$762,2,0) -> 42709 | H14: =VLOOKUP(F14,Покупатели!$F$2:$N$762,3,0) -> МВД РК | I14: =VLOOKUP(C14,Покупатели!$C$2:$M$805,7,0) -> 001128551373 | J14: =IFERROR(__xludf.DUMMYFUNCTION("JOIN("" "", VLOOKUP(C14,Покупатели,8,0),VLOOKUP(C14,Покупатели,9,0),VLOOKUP(C14,Покупатели,10,0),VLOOKUP(C14,Покупатели,11,0))"),"Акмолинская область с.Астраханка Маяковского 2/2") -> Акмолинская область с.Астраханка Маяковского 2/2 | K14: =VLOOKUP(C14,Покупатели,12,0) -> 87057433768 | L14: =VLOOKUP(A14,Реестр_Договоров,4,0) -> MX4000002R0001653 | M14: =VLOOKUP(L14,ПРИЦЕПЫ,11,0) -> 002-2013E30Q13-OK | N14: =VLOOKUP(L14,ПРИЦЕПЫ,2,0) -> Прицеп 2,0*1,25 м (до 750 кг.) | O14: =VLOOKUP(L14,ПРИЦЕПЫ,10,0) -> 1 ось | P14: =YEAR(VLOOKUP(L14,ПРИЦЕПЫ,7,0)) -> 2024 | Q14: =VLOOKUP(M14,матрица,16,0) -> 3150*1700*900 | R14: =VLOOKUP(M14,матрица,17,0) -> 2000*1250*300 | S14: =VLOOKUP(O14,ОТТС!$A$2:$B$3,2,0) -> ТС KZ Е-KZ.0317.00251 от 28.02.2023 | T14: 360000 | U14: =VLOOKUP(L14,ПРИЦЕПЫ,9,0) -> Астана
A15: 1174 | B15: =VLOOKUP(A15,'Реестр договоров'!$A$2:$D$55,2,0) -> 45463 | C15: =VLOOKUP(A15,Реестр_Договоров,3,0) -> Ягминас | D15: =VLOOKUP(C15,Покупатели,2,0) -> Андрей | E15: =VLOOKUP(C15,Покупатели,3,0) -> Николаевич | F15: =VLOOKUP(C15,Покупатели,4,0) -> 047758074 | G15: =VLOOKUP(F15,Покупатели!$F$2:$N$762,2,0) -> 43965 | H15: =VLOOKUP(F15,Покупатели!$F$2:$N$762,3,0) -> МВД РК | I15: =VLOOKUP(C15,Покупатели!$C$2:$M$805,7,0) -> 850321351214 | J15: =IFERROR(__xludf.DUMMYFUNCTION("JOIN("" "", VLOOKUP(C15,Покупатели,8,0),VLOOKUP(C15,Покупатели,9,0),VLOOKUP(C15,Покупатели,10,0),VLOOKUP(C15,Покупатели,11,0))"),"Астана район Байконыр ул.Коксенгир д.12 кв.2") -> Астана район Байконыр ул.Коксенгир д.12 кв.2 | K15: =VLOOKUP(C15,Покупатели,12,0) -> 87073831806 | L15: =VLOOKUP(A15,Реестр_Договоров,4,0) -> MX4000002R0001654 | M15: =VLOOKUP(L15,ПРИЦЕПЫ,11,0) -> 002-2013E50Q13-OK | N15: =VLOOKUP(L15,ПРИЦЕПЫ,2,0) -> Прицеп 2,0*1,25 м (до 750 кг.) | O15: =VLOOKUP(L15,ПРИЦЕПЫ,10,0) -> 1 ось | P15: =YEAR(VLOOKUP(L15,ПРИЦЕПЫ,7,0)) -> 2024 | Q15: =VLOOKUP(M15,матрица,16,0) -> 3150*1700*1070 | R15: =VLOOKUP(M15,матрица,17,0) -> 2000*1250*500 | S15: =VLOOKUP(O15,ОТТС!$A$2:$B$3,2,0) -> ТС KZ Е-KZ.0317.00251 от 28.02.2023 | T15: 340000 | U15: =VLOOKUP(L15,ПРИЦЕПЫ,9,0) -> Астана
A16: 1175 | B16: =VLOOKUP(A16,'Реестр договоров'!$A$2:$D$55,2,0) -> 45464 | C16: =VLOOKUP(A16,Реестр_Договоров,3,0) -> Костюков1 | D16: =VLOOKUP(C16,Покупатели,2,0) -> Александр | E16: =VLOOKUP(C16,Покупатели,3,0) -> Дмитриевич | F16: =VLOOKUP(C16,Покупатели,4,0) -> 054358115 | G16: =VLOOKUP(F16,Покупатели!$F$2:$N$762,2,0) -> 45174 | H16: =VLOOKUP(F16,Покупатели!$F$2:$N$762,3,0) -> МВД РК | I16: =VLOOKUP(C16,Покупатели!$C$2:$M$805,7,0) -> 940702301406 | J16: =IFERROR(__xludf.DUMMYFUNCTION("JOIN("" "", VLOOKUP(C16,Покупатели,8,0),VLOOKUP(C16,Покупатели,9,0),VLOOKUP(C16,Покупатели,10,0),VLOOKUP(C16,Покупатели,11,0))"),"Алматинская область город Алматы мкр.Орбита 2 дом 18, кв.26") -> Алматинская область город Алматы мкр.Орбита 2 дом 18, кв.26 | K16: =VLOOKUP(C16,Покупатели,12,0) -> 87477894960 | L16: =VLOOKUP(A16,Реестр_Договоров,4,0) -> MX4000002R0001506 | M16: =VLOOKUP(L16,ПРИЦЕПЫ,11,0) -> 002-2513E30Q13-OK | N16: =VLOOKUP(L16,ПРИЦЕПЫ,2,0) -> Прицеп 2,5*1,25 м (до 750 кг.) | O16: =VLOOKUP(L16,ПРИЦЕПЫ,10,0) -> 1 ось | P16: =YEAR(VLOOKUP(L16,ПРИЦЕПЫ,7,0)) -> 2024 | Q16: =VLOOKUP(M16,матрица,16,0) -> 3650*1700*900 | R16: =VLOOKUP(M16,матрица,17,0) -> 2500*1250*300 | S16: =VLOOKUP(O16,ОТТС!$A$2:$B$3,2,0) -> ТС KZ Е-KZ.0317.00251 от 28.02.2023 | T16: 380000 | U16: =VLOOKUP(L16,ПРИЦЕПЫ,9,0) -> Алматы
A17: 1176 | B17: =VLOOKUP(A17,'Реестр договоров'!$A$2:$D$55,2,0) -> 45464 | C17: =VLOOKUP(A17,Реестр_Договоров,3,0) -> Байзаков | D17: =VLOOKUP(C17,Покупатели,2,0) -> Айбар | E17: =VLOOKUP(C17,Покупатели,3,0) -> Сайлауович | F17: =VLOOKUP(C17,Покупатели,4,0) -> 053400172 | G17: =VLOOKUP(F17,Покупатели!$F$2:$N$762,2,0) -> 44763 | H17: =VLOOKUP(F17,Покупатели!$F$2:$N$762,3,0) -> МВД РК | I17: =VLOOKUP(C17,Покупатели!$C$2:$M$805,7,0) -> 631102301472 | J17: =IFERROR(__xludf.DUMMYFUNCTION("JOIN("" "", VLOOKUP(C17,Покупатели,8,0),VLOOKUP(C17,Покупатели,9,0),VLOOKUP(C17,Покупатели,10,0),VLOOKUP(C17,Покупатели,11,0))"),"город Астана мкр. Шубары ул.Каратай Турысова 36") -> город Астана мкр. Шубары ул.Каратай Турысова 36 | K17: =VLOOKUP(C17,Покупатели,12,0) -> 87051000909 | L17: =VLOOKUP(A17,Реестр_Договоров,4,0) -> MX4000002R0001680 | M17: 002-2013E30Q13-OK30 | N17: =VLOOKUP(L17,ПРИЦЕПЫ,2,0) -> Прицеп 2,0*1,25 м (до 750 кг.) | O17: =VLOOKUP(L17,ПРИЦЕПЫ,10,0) -> 1 ось | P17: =YEAR(VLOOKUP(L17,ПРИЦЕПЫ,7,0)) -> 2024 | Q17: 3150*1700*900 | R17: 2000*1250*300 | S17: =VLOOKUP(O17,ОТТС!$A$2:$B$3,2,0) -> ТС KZ Е-KZ.0317.00251 от 28.02.2023 | T17: 350000 | U17: =VLOOKUP(L17,ПРИЦЕПЫ,9,0) -> Астана
A18: 1177 | B18: =VLOOKUP(A18,'Реестр договоров'!$A$2:$D$80,2,0) -> 45464 | C18: =VLOOKUP(A18,Реестр_Договоров,3,0) -> Оспанова | D18: =VLOOKUP(C18,Покупатели,2,0) -> Гульден | E18: =VLOOKUP(C18,Покупатели,3,0) -> Сериковна | F18: =VLOOKUP(C18,Покупатели,4,0) -> 050380494 | G18: =VLOOKUP(F18,Покупатели!$F$2:$N$762,2,0) -> 44321 | H18: =VLOOKUP(F18,Покупатели!$F$2:$N$762,3,0) -> МВД РК | I18: =VLOOKUP(C18,Покупатели!$C$2:$M$805,7,0) -> 860401450774 | J18: =IFERROR(__xludf.DUMMYFUNCTION("JOIN("" "", VLOOKUP(C18,Покупатели,8,0),VLOOKUP(C18,Покупатели,9,0),VLOOKUP(C18,Покупатели,10,0),VLOOKUP(C18,Покупатели,11,0))"),"город Астана район Алматы ул.Жансугурулы д.4/3 КВ.225") -> город Астана район Алматы ул.Жансугурулы д.4/3 КВ.225 | K18: =VLOOKUP(C18,Покупатели,12,0) -> 87078692966 | L18: =VLOOKUP(A18,Реестр_Договоров,4,0) -> MX4000002R0001497 | M18: =VLOOKUP(L18,ПРИЦЕПЫ,11,0) -> 002-2013E50Q13-OK | N18: =VLOOKUP(L18,ПРИЦЕПЫ,2,0) -> Прицеп 2,0*1,25 м (до 750 кг.) | O18: =VLOOKUP(L18,ПРИЦЕПЫ,10,0) -> 1 ось | P18: =YEAR(VLOOKUP(L18,ПРИЦЕПЫ,7,0)) -> 2024 | Q18: =VLOOKUP(M18,матрица,16,0) -> 3150*1700*1070 | R18: =VLOOKUP(M18,матрица,17,0) -> 2000*1250*500 | S18: =VLOOKUP(O18,ОТТС!$A$2:$B$3,2,0) -> ТС KZ Е-KZ.0317.00251 от 28.02.2023 | T18: 350000 | U18: =VLOOKUP(L18,ПРИЦЕПЫ,9,0) -> Астана
A19: 1178 | B19: =VLOOKUP(A19,'Реестр договоров'!$A$2:$D$55,2,0) -> 45464 | C19: =VLOOKUP(A19,Реестр_Договоров,3,0) -> Шапарев | D19: =VLOOKUP(C19,Покупатели,2,0) -> Антон | E19: =VLOOKUP(C19,Покупатели,3,0) -> Витальевич | F19: =VLOOKUP(C19,Покупатели,4,0) -> 056014519 | G19: =VLOOKUP(F19,Покупатели!$F$2:$N$762,2,0) -> 45379 | H19: =VLOOKUP(F19,Покупатели!$F$2:$N$762,3,0) -> МЮ РК | I19: =VLOOKUP(C19,Покупатели!$C$2:$M$805,7,0) -> 890806301201 | J19: =IFERROR(__xludf.DUMMYFUNCTION("JOIN("" "", VLOOKUP(C19,Покупатели,8,0),VLOOKUP(C19,Покупатели,9,0),VLOOKUP(C19,Покупатели,10,0),VLOOKUP(C19,Покупатели,11,0))"),"Алматинская область Илийский район, село Мухаметжан Туймебаев ПКСТ Ардагер-Ветеран, 21 линия 41") -> Алматинская область Илийский район, село Мухаметжан Туймебаев ПКСТ Ардагер-Ветеран, 21 линия 41 | K19: =VLOOKUP(C19,Покупатели,12,0) -> 87772906865 | L19: =VLOOKUP(A19,Реестр_Договоров,4,0) -> MX4000002R0001516 | M19: =VLOOKUP(L19,ПРИЦЕПЫ,11,0) -> 002-2513E50Q13-OK | N19: =VLOOKUP(L19,ПРИЦЕПЫ,2,0) -> Прицеп 2,5*1,25 м (до 750 кг.) | O19: =VLOOKUP(L19,ПРИЦЕПЫ,10,0) -> 1 ось | P19: =YEAR(VLOOKUP(L19,ПРИЦЕПЫ,7,0)) -> 2024 | Q19: =VLOOKUP(M19,матрица,16,0) -> 3650*1700*1070 | R19: =VLOOKUP(M19,матрица,17,0) -> 2500*1250*500 | S19: =VLOOKUP(O19,ОТТС!$A$2:$B$3,2,0) -> ТС KZ Е-KZ.0317.00251 от 28.02.2023 | T19: 380000 | U19: =VLOOKUP(L19,ПРИЦЕПЫ,9,0) -> Алматы
A20: 1179 | B20: =VLOOKUP(A20,'Реестр договоров'!$A$2:$D$89,2,0) -> 45464 | C20: =VLOOKUP(A20,Реестр_Договоров,3,0) -> Бикенова | D20: =VLOOKUP(C20,Покупатели,2,0) -> Анаргуль | E20: =VLOOKUP(C20,Покупатели,3,0) -> Косымбековна | F20: =VLOOKUP(C20,Покупатели,4,0) -> 048906928 | G20: =VLOOKUP(F20,Покупатели!$F$2:$N$762,2,0) -> 44105 | H20: =VLOOKUP(F20,Покупатели!$F$2:$N$762,3,0) -> МВД РК | I20: =VLOOKUP(C20,Покупатели!$C$2:$M$805,7,0) -> 700312400633 | J20: =IFERROR(__xludf.DUMMYFUNCTION("JOIN("" "", VLOOKUP(C20,Покупатели,8,0),VLOOKUP(C20,Покупатели,9,0),VLOOKUP(C20,Покупатели,10,0),VLOOKUP(C20,Покупатели,11,0))"),"Акмолинская область Зерендинский район, с. Конысбай Габдуллина 33") -> Акмолинская область Зерендинский район, с. Конысбай Габдуллина 33 | K20: =VLOOKUP(C20,Покупатели,12,0) -> 87087496491 | L20: =VLOOKUP(A20,Реестр_Договоров,4,0) -> MX4000002R0001643 | M20: =VLOOKUP(L20,ПРИЦЕПЫ,11,0) -> 002-2513E50Q13-OK | N20: =VLOOKUP(L20,ПРИЦЕПЫ,2,0) -> Прицеп 2,5*1,25 м (до 750 кг.) | O20: =VLOOKUP(L20,ПРИЦЕПЫ,10,0) -> 1 ось | P20: =YEAR(VLOOKUP(L20,ПРИЦЕПЫ,7,0)) -> 2024 | Q20: =VLOOKUP(M20,матрица,16,0) -> 3650*1700*1070 | R20: =VLOOKUP(M20,матрица,17,0) -> 2500*1250*500 | S20: =VLOOKUP(O20,ОТТС!$A$2:$B$3,2,0) -> ТС KZ Е-KZ.0317.00251 от 28.02.2023 | T20: 330000 | U20: =VLOOKUP(L20,ПРИЦЕПЫ,9,0) -> Кокшетау
A21: 1180 | B21: =VLOOKUP(A21,'Реестр договоров'!$A$2:$D$80,2,0) -> 45464 | C21: =VLOOKUP(A21,Реестр_Договоров,3,0) -> Боровиков | D21: =VLOOKUP(C21,Покупатели,2,0) -> Александр | E21: =VLOOKUP(C21,Покупатели,3,0) -> Викторович | F21: =VLOOKUP(C21,Покупатели,4,0) -> 049617497 | G21: =VLOOKUP(F21,Покупатели!$F$2:$N$762,2,0) -> 44529 | H21: =VLOOKUP(F21,Покупатели!$F$2:$N$762,3,0) -> МВД РК | I21: =VLOOKUP(C21,Покупатели!$C$2:$M$805,7,0) -> 860706300175 | J21: =IFERROR(__xludf.DUMMYFUNCTION("JOIN("" "", VLOOKUP(C21,Покупатели,8,0),VLOOKUP(C21,Покупатели,9,0),VLOOKUP(C21,Покупатели,10,0),VLOOKUP(C21,Покупатели,11,0))"),"г.Алматы мкр.Рахат ул.Шагала 3/1") -> г.Алматы мкр.Рахат ул.Шагала 3/1 | K21: =VLOOKUP(C21,Покупатели,12,0) -> 87080070078 | L21: =VLOOKUP(A21,Реестр_Договоров,4,0) -> MX4000002R0001521 | M21: =VLOOKUP(L21,ПРИЦЕПЫ,11,0) -> 002-2513E30Q13-OK | N21: =VLOOKUP(L21,ПРИЦЕПЫ,2,0) -> Прицеп 2,5*1,25 м (до 750 кг.) | O21: =VLOOKUP(L21,ПРИЦЕПЫ,10,0) -> 1 ось | P21: =YEAR(VLOOKUP(L21,ПРИЦЕПЫ,7,0)) -> 2024 | Q21: =VLOOKUP(M21,матрица,16,0) -> 3650*1700*900 | R21: =VLOOKUP(M21,матрица,17,0) -> 2500*1250*300 | S21: =VLOOKUP(O21,ОТТС!$A$2:$B$3,2,0) -> ТС KZ Е-KZ.0317.00251 от 28.02.2023 | T21: 380000 | U21: =VLOOKUP(L21,ПРИЦЕПЫ,9,0) -> Алматы
A22: 1181 | B22: =VLOOKUP(A22,'Реестр договоров'!$A$2:$D$506,2,0) -> 45465 | C22: =VLOOKUP(A22,Реестр_Договоров,3,0) -> Гаврилюк | D22: =VLOOKUP(C22,Покупатели,2,0) -> Артем | E22: =VLOOKUP(C22,Покупатели,3,0) -> Алексеевич | F22: =VLOOKUP(C22,Покупатели,4,0) -> 050735465 | G22: =VLOOKUP(F22,Покупатели!$F$2:$N$762,2,0) -> 44700 | H22: =VLOOKUP(F22,Покупатели!$F$2:$N$762,3,0) -> МЮ РК | I22: =VLOOKUP(C22,Покупатели!$C$2:$M$805,7,0) -> 841214350939 | J22: =IFERROR(__xludf.DUMMYFUNCTION("JOIN("" "", VLOOKUP(C22,Покупатели,8,0),VLOOKUP(C22,Покупатели,9,0),VLOOKUP(C22,Покупатели,10,0),VLOOKUP(C22,Покупатели,11,0))"),"Жамбульская область с.Кордай ул.Рыскулова 214") -> Жамбульская область с.Кордай ул.Рыскулова 214 | K22: =VLOOKUP(C22,Покупатели,12,0) -> 87776674530 | L22: =VLOOKUP(A22,Реестр_Договоров,4,0) -> MX4000002R0001572 | M22: =VLOOKUP(L22,ПРИЦЕПЫ,11,0) -> 002-2013E50Q13-OK | N22: =VLOOKUP(L22,ПРИЦЕПЫ,2,0) -> Прицеп 2,0*1,25 м (до 750 кг.) | O22: =VLOOKUP(L22,ПРИЦЕПЫ,10,0) -> 1 ось | P22: =YEAR(VLOOKUP(L22,ПРИЦЕПЫ,7,0)) -> 2024 | Q22: =VLOOKUP(M22,матрица,16,0) -> 3150*1700*1070 | R22: =VLOOKUP(M22,матрица,17,0) -> 2000*1250*500 | S22: =VLOOKUP(O22,ОТТС!$A$2:$B$3,2,0) -> ТС KZ Е-KZ.0317.00251 от 28.02.2023 | T22: 320000 | U22: =VLOOKUP(L22,ПРИЦЕПЫ,9,0) -> Алматы
A23: 1182 | B23: =VLOOKUP(A23,'Реестр договоров'!$A$2:$D$80,2,0) -> 45465 | C23: =VLOOKUP(A23,Реестр_Договоров,3,0) -> Каримов | D23: =VLOOKUP(C23,Покупатели,2,0) -> Нуршат | E23: =VLOOKUP(C23,Покупатели,3,0) -> Каримович | F23: =VLOOKUP(C23,Покупатели,4,0) -> 053045761 | G23: =VLOOKUP(F23,Покупатели!$F$2:$N$762,2,0) -> 45021 | H23: =VLOOKUP(F23,Покупатели!$F$2:$N$762,3,0) -> МВД РК | I23: =VLOOKUP(C23,Покупатели!$C$2:$M$805,7,0) -> 900926301536 | J23: =IFERROR(__xludf.DUMMYFUNCTION("JOIN("" "", VLOOKUP(C23,Покупатели,8,0),VLOOKUP(C23,Покупатели,9,0),VLOOKUP(C23,Покупатели,10,0),VLOOKUP(C23,Покупатели,11,0))"),"Алматы Горный гигант Сызганова 89") -> Алматы Горный гигант Сызганова 89 | K23: =VLOOKUP(C23,Покупатели,12,0) -> 87001990026 | L23: =VLOOKUP(A23,Реестр_Договоров,4,0) -> MX4000002R0001481 | M23: =VLOOKUP(L23,ПРИЦЕПЫ,11,0) -> 002-2013E50Q13-OK | N23: =VLOOKUP(L23,ПРИЦЕПЫ,2,0) -> Прицеп 2,0*1,25 м (до 750 кг.) | O23: =VLOOKUP(L23,ПРИЦЕПЫ,10,0) -> 1 ось | P23: =YEAR(VLOOKUP(L23,ПРИЦЕПЫ,7,0)) -> 2024 | Q23: =VLOOKUP(M23,матрица,16,0) -> 3150*1700*1070 | R23: =VLOOKUP(M23,матрица,17,0) -> 2000*1250*500 | S23: =VLOOKUP(O23,ОТТС!$A$2:$B$3,2,0) -> ТС KZ Е-KZ.0317.00251 от 28.02.2023 | T23: 380000 | U23: =VLOOKUP(L23,ПРИЦЕПЫ,9,0) -> Алматы
